[2022-12-27 18:24:05,289] {taskinstance.py:851} INFO - Dependencies all met for <TaskInstance: crypto_data_etl_auto_train_model.get_crypto_trading_data 2022-12-26T07:00:00+00:00 [queued]>
[2022-12-27 18:24:05,297] {taskinstance.py:851} INFO - Dependencies all met for <TaskInstance: crypto_data_etl_auto_train_model.get_crypto_trading_data 2022-12-26T07:00:00+00:00 [queued]>
[2022-12-27 18:24:05,298] {taskinstance.py:1042} INFO - 
--------------------------------------------------------------------------------
[2022-12-27 18:24:05,299] {taskinstance.py:1043} INFO - Starting attempt 3 of 8
[2022-12-27 18:24:05,299] {taskinstance.py:1044} INFO - 
--------------------------------------------------------------------------------
[2022-12-27 18:24:05,315] {taskinstance.py:1063} INFO - Executing <Task(PythonOperator): get_crypto_trading_data> on 2022-12-26T07:00:00+00:00
[2022-12-27 18:24:05,323] {standard_task_runner.py:52} INFO - Started process 11536 to run task
[2022-12-27 18:24:05,327] {standard_task_runner.py:76} INFO - Running: ['airflow', 'tasks', 'run', 'crypto_data_etl_auto_train_model', 'get_crypto_trading_data', '2022-12-26T07:00:00+00:00', '--job-id', '1097', '--pool', 'default_pool', '--raw', '--subdir', 'DAGS_FOLDER/crypto_etl.py', '--cfg-path', '/tmp/tmpo2sbksc1', '--error-file', '/tmp/tmpmuee_kii']
[2022-12-27 18:24:05,331] {standard_task_runner.py:77} INFO - Job 1097: Subtask get_crypto_trading_data
[2022-12-27 18:24:05,377] {logging_mixin.py:104} INFO - Running <TaskInstance: crypto_data_etl_auto_train_model.get_crypto_trading_data 2022-12-26T07:00:00+00:00 [running]> on host 2a76951a993b
[2022-12-27 18:24:05,414] {taskinstance.py:1257} INFO - Exporting the following env vars:
AIRFLOW_CTX_DAG_OWNER=VMD
AIRFLOW_CTX_DAG_ID=crypto_data_etl_auto_train_model
AIRFLOW_CTX_TASK_ID=get_crypto_trading_data
AIRFLOW_CTX_EXECUTION_DATE=2022-12-26T07:00:00+00:00
AIRFLOW_CTX_DAG_RUN_ID=scheduled__2022-12-26T07:00:00+00:00
[2022-12-27 18:24:05,515] {logging_mixin.py:104} INFO - Error message (get_url_data) : HTTPSConnectionPool(host='web-api.coinmarketcap.com', port=443): Max retries exceeded with url: /v1/cryptocurrency/map?symbol=BTC (Caused by NewConnectionError('<urllib3.connection.HTTPSConnection object at 0x7fa186b0c048>: Failed to establish a new connection: [Errno -5] No address associated with hostname',))
[2022-12-27 18:24:05,515] {logging_mixin.py:104} INFO - Error fetching coin id data for coin code {} BTC
[2022-12-27 18:24:05,516] {logging_mixin.py:104} INFO - Error message: HTTPSConnectionPool(host='web-api.coinmarketcap.com', port=443): Max retries exceeded with url: /v1/cryptocurrency/map?symbol=BTC (Caused by NewConnectionError('<urllib3.connection.HTTPSConnection object at 0x7fa186b0c048>: Failed to establish a new connection: [Errno -5] No address associated with hostname',))
[2022-12-27 18:24:05,526] {logging_mixin.py:104} INFO - Error message (get_url_data) : HTTPSConnectionPool(host='web-api.coinmarketcap.com', port=443): Max retries exceeded with url: /v1/cryptocurrency/ohlcv/historical?convert=USD&slug=None&time_end=1672099200&time_start=1671926400 (Caused by NewConnectionError('<urllib3.connection.HTTPSConnection object at 0x7fa186b29c50>: Failed to establish a new connection: [Errno -5] No address associated with hostname',))
[2022-12-27 18:24:05,526] {logging_mixin.py:104} INFO - Error fetching price data for {} for interval '{}' and '{}' BTC 26-12-2022 27-12-2022
[2022-12-27 18:24:05,526] {logging_mixin.py:104} INFO - Error message (download_data) : HTTPSConnectionPool(host='web-api.coinmarketcap.com', port=443): Max retries exceeded with url: /v1/cryptocurrency/ohlcv/historical?convert=USD&slug=None&time_end=1672099200&time_start=1671926400 (Caused by NewConnectionError('<urllib3.connection.HTTPSConnection object at 0x7fa186b29c50>: Failed to establish a new connection: [Errno -5] No address associated with hostname',))
[2022-12-27 18:24:05,527] {taskinstance.py:1455} ERROR - 'NoneType' object is not subscriptable
Traceback (most recent call last):
  File "/home/airflow/.local/lib/python3.6/site-packages/airflow/models/taskinstance.py", line 1112, in _run_raw_task
    self._prepare_and_execute_task_with_callbacks(context, task)
  File "/home/airflow/.local/lib/python3.6/site-packages/airflow/models/taskinstance.py", line 1285, in _prepare_and_execute_task_with_callbacks
    result = self._execute_task(context, task_copy)
  File "/home/airflow/.local/lib/python3.6/site-packages/airflow/models/taskinstance.py", line 1315, in _execute_task
    result = task_copy.execute(context=context)
  File "/home/airflow/.local/lib/python3.6/site-packages/airflow/operators/python.py", line 117, in execute
    return_value = self.execute_callable()
  File "/home/airflow/.local/lib/python3.6/site-packages/airflow/operators/python.py", line 128, in execute_callable
    return self.python_callable(*self.op_args, **self.op_kwargs)
  File "/opt/airflow/dags/datacrawl.py", line 61, in get_crypto_trading_data
    price_df = scraper.get_dataframe()
  File "/home/airflow/.local/lib/python3.6/site-packages/cryptocmd/core.py", line 157, in get_dataframe
    self._download_data(**kwargs)
  File "/home/airflow/.local/lib/python3.6/site-packages/cryptocmd/core.py", line 90, in _download_data
    for _row in coin_data["data"]["quotes"]:
TypeError: 'NoneType' object is not subscriptable
[2022-12-27 18:24:05,531] {taskinstance.py:1503} INFO - Marking task as UP_FOR_RETRY. dag_id=crypto_data_etl_auto_train_model, task_id=get_crypto_trading_data, execution_date=20221226T070000, start_date=20221227T182405, end_date=20221227T182405
[2022-12-27 18:24:05,618] {local_task_job.py:146} INFO - Task exited with return code 1
